I'm sorry, but an uncaught exception occurred.

While running game code:
  File "game/story/Day 1/3.0 physics.rpy", line 238, in script
    if _phys1p2p1t is True:
  File "game/story/Day 1/3.0 physics.rpy", line 238, in <module>
    if _phys1p2p1t is True:
NameError: name '_phys1p2p1t' is not defined

-- Full Traceback ------------------------------------------------------------

Full traceback:
  File "game/story/Day 1/3.0 physics.rpy", line 238, in script
    if _phys1p2p1t is True:
  File "/home/fiendchain/Downloads/sze-the-game-orphan/renpy/ast.py", line 1680, in execute
    if renpy.python.py_eval(condition):
  File "/home/fiendchain/Downloads/sze-the-game-orphan/renpy/python.py", line 1794, in py_eval
    return py_eval_bytecode(code, globals, locals)
  File "/home/fiendchain/Downloads/sze-the-game-orphan/renpy/python.py", line 1788, in py_eval_bytecode
    return eval(bytecode, globals, locals)
  File "game/story/Day 1/3.0 physics.rpy", line 238, in <module>
    if _phys1p2p1t is True:
NameError: name '_phys1p2p1t' is not defined

Linux-4.10.0-35-generic-x86_64-with-debian-stretch-sid
Ren'Py 6.99.13.2919
sze-the game 0.0
