I'm sorry, but an uncaught exception occurred.

While running game code:
  File "game/instances/inventory.rpy", line 1, in script
    init python:
  File "game/instances/inventory.rpy", line 6, in <module>
    "max_items": 10,
TypeError: __init__() takes exactly 5 arguments (4 given)

-- Full Traceback ------------------------------------------------------------

Full traceback:
  File "game/instances/inventory.rpy", line 1, in script
    init python:
  File "C:\Users\Dean Hou\Documents\GitHub\sze-the-game\renpy\ast.py", line 826, in execute
    renpy.python.py_exec_bytecode(self.code.bytecode, self.hide, store=self.store)
  File "C:\Users\Dean Hou\Documents\GitHub\sze-the-game\renpy\python.py", line 1764, in py_exec_bytecode
    exec bytecode in globals, locals
  File "game/instances/inventory.rpy", line 6, in <module>
    "max_items": 10,
TypeError: __init__() takes exactly 5 arguments (4 given)

Windows-8-6.2.9200
Ren'Py 6.99.13.2919
sze-the game 0.0
