I'm sorry, but an uncaught exception occurred.

While running game code:
  File "game/instances/inventory.rpy", line 1, in script
    init python:
  File "game/instances/inventory.rpy", line 12, in <module>
    bag.add(newItem, 1)
TypeError: add() takes exactly 2 arguments (3 given)

-- Full Traceback ------------------------------------------------------------

Full traceback:
  File "game/instances/inventory.rpy", line 1, in script
    init python:
  File "/home/fiendchain/Downloads/sze-the-game/renpy/ast.py", line 826, in execute
    renpy.python.py_exec_bytecode(self.code.bytecode, self.hide, store=self.store)
  File "/home/fiendchain/Downloads/sze-the-game/renpy/python.py", line 1764, in py_exec_bytecode
    exec bytecode in globals, locals
  File "game/instances/inventory.rpy", line 12, in <module>
    bag.add(newItem, 1)
TypeError: add() takes exactly 2 arguments (3 given)

Linux-4.10.0-35-generic-x86_64-with-debian-stretch-sid
Ren'Py 6.99.13.2919
sze-the game 0.0
