I'm sorry, but an uncaught exception occurred.

While running game code:
  File "game/story/Day 1/3.0 physics.rpy", line 2, in script call
    $ renpy.save("autosave")
  File "renpy/common/00start.rpy", line 83, in script
    label _after_load:
  File "renpy/common/000window.rpy", line 91, in _window_auto_callback
    if not store._window_auto:
NameError: global name 'store' is not defined

-- Full Traceback ------------------------------------------------------------

Full traceback:
  File "/home/fiendchain/Downloads/sze-the-game/renpy/bootstrap.py", line 305, in bootstrap
    renpy.main.main()
  File "/home/fiendchain/Downloads/sze-the-game/renpy/main.py", line 499, in main
    run(restart)
  File "/home/fiendchain/Downloads/sze-the-game/renpy/main.py", line 147, in run
    renpy.execution.run_context(True)
  File "/home/fiendchain/Downloads/sze-the-game/renpy/execution.py", line 795, in run_context
    context.run()
  File "game/story/Day 1/3.0 physics.rpy", line 2, in script call
    $ renpy.save("autosave")
  File "renpy/common/00start.rpy", line 83, in script
    label _after_load:
  File "/home/fiendchain/Downloads/sze-the-game/renpy/ast.py", line 768, in execute
    statement_name("label")
  File "/home/fiendchain/Downloads/sze-the-game/renpy/ast.py", line 42, in statement_name
    i(name)
  File "renpy/common/000window.rpy", line 91, in _window_auto_callback
    if not store._window_auto:
NameError: global name 'store' is not defined

Linux-4.10.0-35-generic-x86_64-with-debian-stretch-sid
Ren'Py 6.99.13.2919
sze-the game 0.0
