I'm sorry, but an uncaught exception occurred.

While running game code:
  File "game/instances/game.rpy", line 1, in script
    init -10 python:
  File "game/instances/game.rpy", line 2, in <module>
    game = Game({
NameError: name 'Game' is not defined

-- Full Traceback ------------------------------------------------------------

Full traceback:
  File "game/instances/game.rpy", line 1, in script
    init -10 python:
  File "/home/fiendchain/Downloads/sze-the-game/renpy/ast.py", line 826, in execute
    renpy.python.py_exec_bytecode(self.code.bytecode, self.hide, store=self.store)
  File "/home/fiendchain/Downloads/sze-the-game/renpy/python.py", line 1764, in py_exec_bytecode
    exec bytecode in globals, locals
  File "game/instances/game.rpy", line 2, in <module>
    game = Game({
NameError: name 'Game' is not defined

Linux-4.10.0-35-generic-x86_64-with-debian-stretch-sid
Ren'Py 6.99.13.2919
 
